Workbook
Name UPDATE: 'Data Sheet'!$E$1

Sheet DCF>>

Sheet WACC
B2: Weighted Average Cost of Capital
B4: All figures are in INR unless stated otherwise
B6: Peer Changes
I7: Debt/ | J7: Debt/ | K7: Levered | L7: Unlevered
B8: Name of the Company | E8: Country | F8: Total Debt | G8: Total Equity | H8: Taxrate 1 | I8: Equity | J8: Capital | K8: Beta 2 | L8: Beta 3
B10: Reliance Industries | E10: India | F10: 398000 | G10: 13532 | H10: 0.3 | I10: 0.44 | J10: =F10/(F10+G10) -> 0.96711799 | K10: 1.12 | L10: =K10/(1+(1-H10)*I10) -> 0.85626911
B11: ONGC | E11: India | F11: 176017.8 | G11: 6290.14 | H11: 0.3 | I11: 0.48 | J11: =F11/(F11+G11) -> 0.96549717 | K11: 0.726 | L11: =K11/(1+(1-H11)*I11) -> 0.54341317
B12: Coal India | E12: India | F12: 14072.18 | G12: 6162.73 | H12: 0.3 | I12: 0.12 | J12: =F12/(F12+G12) -> 0.6954407 | K12: 1.11 | L12: =K12/(1+(1-H12)*I12) -> 1.0239852
B13: IOCL | E13: India | F13: 131822.39 | G13: 13771.56 | H13: 0.3 | I13: 0.6 | J13: =F13/(F13+G13) -> 0.90541118 | K13: 0.84 | L13: =K13/(1+(1-H13)*I13) -> 0.5915493
B14: BPCL | E14: India | F14: 54424.42 | G14: 4272.58 | H14: 0.3 | I14: 0.54 | J14: =F14/(F14+G14) -> 0.92720957 | K14: 0.74 | L14: =K14/(1+(1-H14)*I14) -> 0.53701016
G16: Average | H16: =AVERAGE(H10:H14) -> 0.3 | I16: =AVERAGE(I10:I14) -> 0.436 | J16: =AVERAGE(J10:J14) -> 0.89213532 | K16: =AVERAGE(K10:K14) -> 0.9072 | L16: =AVERAGE(L10:L14) -> 0.7104454
G17: Median | H17: =MEDIAN(H10:H14) -> 0.3 | I17: =MEDIAN(I10:I14) -> 0.48 | J17: =MEDIAN(J10:J14) -> 0.92720957 | K17: =MEDIAN(K10:K14) -> 0.84 | L17: =MEDIAN(L10:L14) -> 0.5915493
B21: Cost of Debt | G21: Cost of Equity
B23: Pre-Tax Cost of Debt | E23: 0.0679 | G23: Risk Free Rate | L23: 0.0711
B24: Tax Rate | E24: 0.3 | G24: Equity Risk Premium | L24: ='Market Return'!G7-WACC!L23 -> 0.080392308
B25: Post-Tax Cost of Debt | E25: =E23*(1-E24) -> 0.04753 | G25: Leverated Beta 1 | L25: =IFERROR(Beta!L12,0) -> 1.087289
G26: Cost of Equity | L26: =L23+L24*L25 -> 0.15850967
B30: Capital Structure | G30: Levered Beta
D32: Current | E32: Target | G32: Comps Mediam Unlevered Beta | L32: =L17 -> 0.5915493
B33: Total Debt | C33: =F10 -> 398000 | D33: =C33/$C$35 -> 0.96711799 | E33: =J17 -> 0.92720957 | G33: Target Debt/Equity | L33: =E37 -> 12.738069
B34: Market Capitalixation | C34: =G10 -> 13532 | D34: =C34/$C$35 -> 0.032882012 | E34: =E35-E33 -> 0.072790432 | G34: Tax Rate | L34: =E24 -> 0.3
B35: Total Capital | C35: =SUM(C33,C34) -> 411532 | D35: =C35/$C$35 -> 1 | E35: =D35 -> 1 | G35: Levered Beta | L35: =L32*(1+(1-L34)*L33) -> 5.8661864
B37: Debt/Equity | D37: =D33/D34 -> 29.411765 | E37: =E33/E34 -> 12.738069 | G37: Weighted Average Cost of Capital
B39: Notes: | K39: Total Cost | L39: Total Weight
B40: 1.Tax Rate considered as marginal tax rate for the country | G40: Debt | K40: =E25 -> 0.04753 | L40: =E33 -> 0.92720957
B41: 2.Levered Beta Is based on 5 year monthly data | G41: Equity | K41: =L26 -> 0.15850967 | L41: =E34 -> 0.072790432
B42: 3. Unlevered Beta = Levered Beta/1+(1-Tax Rate)*Debt/Equity) | G42: Weighted Average Cost of Capital | L42: =SUMPRODUCT(K40:K41,L40:L41) -> 0.055608258
B43: 4. levered Beta = UnLevered Beta*1+(1-Tax Rate)*Debt/Equity)

Sheet Beta
B2: Regression Data - 2 Years Weekly
B4: Reliance Industries Weekly Returns | G4: Nifty 50 Weekly Returns | K4: Beta Drifting | O4: Beta 1 | P4: =SLOPE(D8:D111,H8:H111) -> 1.1163854
O5: Beta 2 | P5: =_xlfn.COVARIANCE.S(D8:D111,H8:H111)/_xlfn.VAR.S(H8:H111) -> 1.1163854
B6: Date | C6: Adj Close | D6: Weekly Return | F6: Date | G6: Adj Close | H6: Weekly Return | K6: Levered Beta Rate | L6: =P4 -> 1.1163854 | O6: Beta 3 | P6: =P25 -> 1.1163854
B7: 45431 | C7: 1469.3745 | F7: 45431 | G7: 22957.1 | K7: Raw Beta Weight | L7: 0.75
B8: 45438 | C8: 1419.8907 | D8: =C8/C7-1 -> -0.033676754 | F8: 45438 | G8: 22530.699 | H8: =G8/G7-1 -> -0.018573792 | O8: SUMMARY OUTPUT
B9: 45445 | C9: 1459.15 | D9: =C9/C8-1 -> 0.027649506 | F9: 45445 | G9: 23290.15 | H9: =G9/G8-1 -> 0.033707395 | K9: Market Beta | L9: 1
B10: 45452 | C10: 1466.6945 | D10: =C10/C9-1 -> 0.0051704304 | F10: 45452 | G10: 23465.6 | H10: =G10/G9-1 -> 0.0075331939 | K10: Market Beta Weight | L10: 0.25 | O10: Regression Statistics
B11: 45459 | C11: 1443.5159 | D11: =C11/C10-1 -> -0.015803284 | F11: 45459 | G11: 23501.1 | H11: =G11/G10-1 -> 0.0015128529 | O11: Multiple R | P11: 0.67255032
B12: 45466 | C12: 1553.8989 | D12: =C12/C11-1 -> 0.076468198 | F12: 45466 | G12: 24010.6 | H12: =G12/G11-1 -> 0.021679837 | K12: Adjusted Beta | L12: =(L6*L7)+(L9*L10) -> 1.087289 | O12: R Square | P12: 0.45232393
B13: 45473 | C13: 1576.9532 | D13: =C13/C12-1 -> 0.014836436 | F13: 45473 | G13: 24323.85 | H13: =G13/G12-1 -> 0.013046321 | O13: Adjusted R Square | P13: 0.44695456
B14: 45480 | C14: 1584.9938 | D14: =C14/C13-1 -> 0.0050987734 | F14: 45480 | G14: 24502.15 | H14: =G14/G13-1 -> 0.0073302863 | O14: Standard Error | P14: 0.023202364
B15: 45487 | C15: 1543.7242 | D15: =C15/C14-1 -> -0.026037661 | F15: 45487 | G15: 24530.9 | H15: =G15/G14-1 -> 0.0011733664 | O15: Observations | P15: 104
B16: 45494 | C16: 1497.9381 | D16: =C16/C15-1 -> -0.029659528 | F16: 45494 | G16: 24834.85 | H16: =G16/G15-1 -> 0.012390463
B17: 45501 | C17: 1488.3092 | D17: =C17/C16-1 -> -0.0064281069 | F17: 45501 | G17: 24717.699 | H17: =G17/G16-1 -> -0.0047171774 | O17: ANOVA
B18: 45508 | C18: 1463.4683 | D18: =C18/C17-1 -> -0.016690713 | F18: 45508 | G18: 24367.5 | H18: =G18/G17-1 -> -0.014167954 | P18: df | Q18: SS | R18: MS | S18: F | T18: Significance F
B19: 45515 | C19: 1467.3396 | D19: =C19/C18-1 -> 0.0026453173 | F19: 45515 | G19: 24541.15 | H19: =G19/G18-1 -> 0.0071263113 | O19: Regression | P19: 1 | Q19: 0.045351373 | R19: 0.045351373 | S19: 84.241476 | T19: 5.3535654e-15
B20: 45522 | C20: 1488.9545 | D20: =C20/C19-1 -> 0.014730651 | F20: 45522 | G20: 24823.15 | H20: =G20/G19-1 -> 0.011490904 | O20: Residual | P20: 102 | Q20: 0.054911669 | R20: 0.0005383497
B21: 45529 | C21: 1503.6198 | D21: =C21/C20-1 -> 0.0098493833 | F21: 45529 | G21: 25235.9 | H21: =G21/G20-1 -> 0.016627624 | O21: Total | P21: 103 | Q21: 0.10026304
B22: 45536 | C22: 1458.9978 | D22: =C22/C21-1 -> -0.029676351 | F22: 45536 | G22: 24852.15 | H22: =G22/G21-1 -> -0.015206511
B23: 45543 | C23: 1466.7668 | D23: =C23/C22-1 -> 0.0053249175 | F23: 45543 | G23: 25356.5 | H23: =G23/G22-1 -> 0.020294003 | P23: Coefficients | Q23: Standard Error | R23: t Stat | S23: P-value | T23: Lower 95% | U23: Upper 95% | V23: Lower 95.0% | W23: Upper 95.0%
B24: 45550 | C24: 1480.014 | D24: =C24/C23-1 -> 0.0090315597 | F24: 45550 | G24: 25790.949 | H24: =G24/G23-1 -> 0.017133643 | O24: Intercept | P24: -0.00098141746 | Q24: 0.0022757383 | R24: -0.43125233 | S24: 0.66719498 | T24: -0.0054953336 | U24: 0.0035324987 | V24: -0.0054953336 | W24: 0.0035324987
B25: 45557 | C25: 1520.1039 | D25: =C25/C24-1 -> 0.027087475 | F25: 45557 | G25: 26178.949 | H25: =G25/G24-1 -> 0.015044037 | O25: X Variable 1 | P25: 1.1163854 | Q25: 0.12163293 | R25: 9.1783155 | S25: 5.3535654e-15 | T25: 0.87512705 | U25: 1.3576437 | V25: 0.87512705 | W25: 1.3576437
B26: 45564 | C26: 1381.0094 | D26: =C26/C25-1 -> -0.091503274 | F26: 45564 | G26: 25014.6 | H26: =G26/G25-1 -> -0.04447656
B27: 45571 | C27: 1366.6417 | D27: =C27/C26-1 -> -0.010403749 | F27: 45571 | G27: 24964.25 | H27: =G27/G26-1 -> -0.0020128089
B28: 45578 | C28: 1353.8927 | D28: =C28/C27-1 -> -0.009328724 | F28: 45578 | G28: 24854.051 | H28: =G28/G27-1 -> -0.0044142812
B29: 45585 | C29: 1322.5677 | D29: =C29/C28-1 -> -0.023136953 | F29: 45585 | G29: 24180.801 | H29: =G29/G28-1 -> -0.02708814
B30: 45592 | C30: 1333.3248 | D30: =C30/C29-1 -> 0.0081334813 | F30: 45592 | G30: 24304.35 | H30: =G30/G29-1 -> 0.005109377
B31: 45599 | C31: 1278.6432 | D31: =C31/C30-1 -> -0.041011492 | F31: 45599 | G31: 24148.199 | H31: =G31/G30-1 -> -0.006424792
B32: 45606 | C32: 1262.5575 | D32: =C32/C31-1 -> -0.012580283 | F32: 45606 | G32: 23532.699 | H32: =G32/G31-1 -> -0.025488443
B33: 45613 | C33: 1260.3662 | D33: =C33/C32-1 -> -0.0017355916 | F33: 45613 | G33: 23907.25 | H33: =G33/G32-1 -> 0.015916184
B34: 45620 | C34: 1287.0596 | D34: =C34/C33-1 -> 0.02117905 | F34: 45620 | G34: 24131.1 | H34: =G34/G33-1 -> 0.0093632521
B35: 45627 | C35: 1306.3326 | D35: =C35/C34-1 -> 0.014974498 | F35: 45627 | G35: 24677.801 | H35: =G35/G34-1 -> 0.02265546
B36: 45634 | C36: 1267.7866 | D36: =C36/C35-1 -> -0.029507048 | F36: 45634 | G36: 24768.301 | H36: =G36/G35-1 -> 0.0036672636
B37: 45641 | C37: 1200.5054 | D37: =C37/C36-1 -> -0.053069853 | F37: 45641 | G37: 23587.5 | H37: =G37/G36-1 -> -0.047673871
... B111: 46159 | C111: 1324.1 | D111: =C111/C110-1 -> -0.0092038676 | F111: 46159 | G111: 23536.85 | H111: =G111/G110-1 -> -0.00451077

Sheet FInancials>>

Sheet Ratio Analysis
B2: ="Ratio Analysis- "&'Data Sheet'!B1 -> Ratio Analysis- RELIANCE INDUSTRIES LTD
B3: Years | C3: ='Data Sheet'!B16 -> 42825 | D3: ='Data Sheet'!C16 -> 43190 | E3: ='Data Sheet'!D16 -> 43555 | F3: ='Data Sheet'!E16 -> 43921 | G3: ='Data Sheet'!F16 -> 44286 | H3: ='Data Sheet'!G16 -> 44651 | I3: ='Data Sheet'!H16 -> 45016 | J3: ='Data Sheet'!I16 -> 45382 | ... L3: ='Data Sheet'!K16 -> 46112 | N3: Mean | O3: Median
B5: SalesGrowth | D5: =IFERROR(HistoricalFS!D8,0) -> 0.28579654 | E5: =IFERROR(HistoricalFS!E8,0) -> 0.45420561 | F5: =IFERROR(HistoricalFS!F8,0) -> 0.0498683 | G5: =IFERROR(HistoricalFS!G8,0) -> -0.21849604 | H5: =IFERROR(HistoricalFS!H8,0) -> 0.48973316 | I5: =IFERROR(HistoricalFS!I8,0) -> 0.26159502 | J5: =IFERROR(HistoricalFS!J8,0) -> 0.025838776 | K5: =IFERROR(HistoricalFS!K8,0) -> 0.070941147 | L5: =IFERROR(HistoricalFS!L8,0) -> 0.098044287 | N5: =IFERROR(AVERAGE(D5:L5),0) -> 0.16861409 | O5: =IFERROR(MEDIAN(D5:L5),0) -> 0.098044287
B6: EBITDAGrowth | D6: =IFERROR(HistoricalFS!D19/HistoricalFS!C19-1,0) -> 0.33595058 | E6: =IFERROR(HistoricalFS!E19/HistoricalFS!D19-1,0) -> 0.24900248 | F6: =IFERROR(HistoricalFS!F19/HistoricalFS!E19-1,0) -> 0.055905716 | G6: =IFERROR(HistoricalFS!G19/HistoricalFS!F19-1,0) -> 0.05505131 | H6: =IFERROR(HistoricalFS!H19/HistoricalFS!G19-1,0) -> 0.24179923 | I6: =IFERROR(HistoricalFS!I19/HistoricalFS!H19-1,0) -> 0.204063 | J6: =IFERROR(HistoricalFS!J19/HistoricalFS!I19-1,0) -> 0.15519185 | K6: =IFERROR(HistoricalFS!K19/HistoricalFS!J19-1,0) -> 0.028784564 | L6: =IFERROR(HistoricalFS!L19/HistoricalFS!K19-1,0) -> 0.13351179 | N6: =IFERROR(AVERAGE(D6:L6),0) -> 0.16214006 | O6: =IFERROR(MEDIAN(D6:L6),0) -> 0.15519185
B7: EBIT Growth | D7: =IFERROR(HistoricalFS!D30/HistoricalFS!C30-1,0) -> 0.23460059 | E7: =IFERROR(HistoricalFS!E30/HistoricalFS!D30-1,0) -> 0.11736738 | F7: =IFERROR(HistoricalFS!F30/HistoricalFS!E30-1,0) -> -0.029351585 | G7: =IFERROR(HistoricalFS!G30/HistoricalFS!F30-1,0) -> 0.034604335 | H7: =IFERROR(HistoricalFS!H30/HistoricalFS!G30-1,0) -> 0.51124213 | I7: =IFERROR(HistoricalFS!I30/HistoricalFS!H30-1,0) -> 0.12705363 | J7: =IFERROR(HistoricalFS!J30/HistoricalFS!I30-1,0) -> 0.10454776 | K7: =IFERROR(HistoricalFS!K30/HistoricalFS!J30-1,0) -> 0.016072455 | L7: =IFERROR(HistoricalFS!L30/HistoricalFS!K30-1,0) -> 0.16171935 | N7: =IFERROR(AVERAGE(D7:L7),0) -> 0.14198401 | O7: =IFERROR(MEDIAN(D7:L7),0) -> 0.11736738
B8: Net Profit Growth | D8: =IFERROR(HistoricalFS!D36/HistoricalFS!C36-1,0) -> 0.20939899 | E8: =IFERROR(HistoricalFS!E36/HistoricalFS!D36-1,0) -> 0.10412971 | F8: =IFERROR(HistoricalFS!F36/HistoricalFS!E36-1,0) -> 0.0010793985 | G8: =IFERROR(HistoricalFS!G36/HistoricalFS!F36-1,0) -> 0.34751755 | H8: =IFERROR(HistoricalFS!H36/HistoricalFS!G36-1,0) -> 0.26249093 | I8: =IFERROR(HistoricalFS!I36/HistoricalFS!H36-1,0) -> 0.092018572 | J8: =IFERROR(HistoricalFS!J36/HistoricalFS!I36-1,0) -> 0.061345967 | K8: =IFERROR(HistoricalFS!K36/HistoricalFS!J36-1,0) -> 0.027393079 | L8: =IFERROR(HistoricalFS!L36/HistoricalFS!K36-1,0) -> 0.18348249 | N8: =IFERROR(AVERAGE(D8:L8),0) -> 0.1432063 | O8: =IFERROR(MEDIAN(D8:L8),0) -> 0.10412971
B9: Dividend Growth | D9: =IFERROR(HistoricalFS!D44/HistoricalFS!C44,0) -> 1.1205897 | E9: =IFERROR(HistoricalFS!E44/HistoricalFS!D44,0) -> 1.0833676 | F9: =IFERROR(HistoricalFS!F44/HistoricalFS!E44,0) -> 1.0696059 | G9: =IFERROR(HistoricalFS!G44/HistoricalFS!F44,0) -> 1.1678869 | H9: =IFERROR(HistoricalFS!H44/HistoricalFS!G44,0) -> 1.1241571 | I9: =IFERROR(HistoricalFS!I44/HistoricalFS!H44,0) -> 1.1250499 | J9: =IFERROR(HistoricalFS!J44/HistoricalFS!I44,0) -> 1.1110947 | K9: =IFERROR(HistoricalFS!K44/HistoricalFS!J44,0) -> 1.0999187 | L9: =IFERROR(HistoricalFS!L44/HistoricalFS!K44,0) -> 1.090901 | N9: =IFERROR(AVERAGE(D9:L9),0) -> 1.1102857 | O9: =IFERROR(MEDIAN(D9:L9),0) -> 1.1110947
B11: Gross Margin | C11: =IFERROR(HistoricalFS!C14,0) -> 0.23466709 | D11: =IFERROR(HistoricalFS!D14,0) -> 0.25444511 | E11: =IFERROR(HistoricalFS!E14,0) -> 0.24728462 | F11: =IFERROR(HistoricalFS!F14,0) -> 0.26714867 | G11: =IFERROR(HistoricalFS!G14,0) -> 0.34380783 | H11: =IFERROR(HistoricalFS!H14,0) -> 0.2770325 | I11: =IFERROR(HistoricalFS!I14,0) -> 0.26282753 | J11: =IFERROR(HistoricalFS!J14,0) -> 0.29297663 | ... L11: =IFERROR(HistoricalFS!L14,0) -> 0.34732633 | N11: =IFERROR(AVERAGE(C11:L11),0) -> 0.2818552 | O11: =IFERROR(MEDIAN(C11:L11),0) -> 0.27209059
B12: EBITDA Margin | C12: =IFERROR(HistoricalFS!C20,0) -> 0.18268883 | D12: =IFERROR(HistoricalFS!D20,0) -> 0.18981483 | E12: =IFERROR(HistoricalFS!E20,0) -> 0.16303003 | F12: =IFERROR(HistoricalFS!F20,0) -> 0.16396756 | G12: =IFERROR(HistoricalFS!G20,0) -> 0.22136061 | H12: =IFERROR(HistoricalFS!H20,0) -> 0.18451991 | I12: =IFERROR(HistoricalFS!I20,0) -> 0.17610532 | J12: =IFERROR(HistoricalFS!J20,0) -> 0.19831131 | ... L12: =IFERROR(HistoricalFS!L20,0) -> 0.1966584 | N12: =IFERROR(AVERAGE(C12:L12),0) -> 0.18669618 | O12: =IFERROR(MEDIAN(C12:L12),0) -> 0.18716737
B13: EBIT Margin | C13: =IFERROR(HistoricalFS!C25/HistoricalFS!C6,0) -> 0.14437382 | D13: =IFERROR(HistoricalFS!D25/HistoricalFS!D6,0) -> 0.14706913 | E13: =IFERROR(HistoricalFS!E25/HistoricalFS!E6,0) -> 0.12619625 | F13: =IFERROR(HistoricalFS!F25/HistoricalFS!F6,0) -> 0.1267566 | G13: =IFERROR(HistoricalFS!G25/HistoricalFS!G6,0) -> 0.16437669 | H13: =IFERROR(HistoricalFS!H25/HistoricalFS!H6,0) -> 0.14164794 | I13: =IFERROR(HistoricalFS!I25/HistoricalFS!I6,0) -> 0.13011812 | J13: =IFERROR(HistoricalFS!J25/HistoricalFS!J6,0) -> 0.14177106 | ... L13: =IFERROR(HistoricalFS!L25/HistoricalFS!L6,0) -> 0.1420926 | N13: =IFERROR(AVERAGE(C13:L13),0) -> 0.13997193 | O13: =IFERROR(MEDIAN(C13:L13),0) -> 0.1417095
B14: EBT Margin | C14: =IFERROR(HistoricalFS!C31,0) -> 0.13171072 | D14: =IFERROR(HistoricalFS!D31,0) -> 0.12646646 | E14: =IFERROR(HistoricalFS!E31,0) -> 0.09717298 | F14: =IFERROR(HistoricalFS!F31,0) -> 0.089840601 | G14: =IFERROR(HistoricalFS!G31,0) -> 0.11893667 | H14: =IFERROR(HistoricalFS!H31,0) -> 0.12065389 | I14: =IFERROR(HistoricalFS!I31,0) -> 0.10778689 | J14: =IFERROR(HistoricalFS!J31,0) -> 0.116057 | ... L14: =IFERROR(HistoricalFS!L31,0) -> 0.1164962 | N14: =IFERROR(AVERAGE(C14:L14),0) -> 0.11352323 | O14: =IFERROR(MEDIAN(C14:L14),0) -> 0.1162766
B15: Net Profit Margin | C15: =IFERROR(HistoricalFS!C37,0) -> 0.09814972 | D15: =IFERROR(HistoricalFS!D37,0) -> 0.092318006 | E15: =IFERROR(HistoricalFS!E37,0) -> 0.070093976 | F15: =IFERROR(HistoricalFS!F37,0) -> 0.066836607 | G15: =IFERROR(HistoricalFS!G37,0) -> 0.11524382 | H15: =IFERROR(HistoricalFS!H37,0) -> 0.097664657 | I15: =IFERROR(HistoricalFS!I37,0) -> 0.084537127 | J15: =IFERROR(HistoricalFS!J37,0) -> 0.087463197 | ... L15: =IFERROR(HistoricalFS!L37,0) -> 0.090435378 | N15: =IFERROR(AVERAGE(C15:L15),0) -> 0.088664914 | O15: =IFERROR(MEDIAN(C15:L15),0) -> 0.088949287
B17: SalesExpense%Sales | C17: =IFERROR(HistoricalFS!C17,0) -> 0.05197826 | D17: =IFERROR(HistoricalFS!D17,0) -> 0.06463028 | E17: =IFERROR(HistoricalFS!E17,0) -> 0.084254588 | F17: =IFERROR(HistoricalFS!F17,0) -> 0.10318111 | G17: =IFERROR(HistoricalFS!G17,0) -> 0.12244723 | H17: =IFERROR(HistoricalFS!H17,0) -> 0.092512592 | I17: =IFERROR(HistoricalFS!I17,0) -> 0.086722212 | J17: =IFERROR(HistoricalFS!J17,0) -> 0.094665316 | ... L17: =IFERROR(HistoricalFS!L17,0) -> 0.15066793 | N17: =IFERROR(AVERAGE(C17:L17),0) -> 0.095159025 | O17: =IFERROR(MEDIAN(C17:L17),0) -> 0.093588954
B18: Depreciation%Sales | C18: =IFERROR(HistoricalFS!C27/HistoricalFS!C6,0) -> 0.038315008 | D18: =IFERROR(HistoricalFS!D27/HistoricalFS!D6,0) -> 0.042745693 | E18: =IFERROR(HistoricalFS!E27/HistoricalFS!E6,0) -> 0.03683378 | F18: =IFERROR(HistoricalFS!F27/HistoricalFS!F6,0) -> 0.037210963 | G18: =IFERROR(HistoricalFS!G27/HistoricalFS!G6,0) -> 0.056983918 | H18: =IFERROR(HistoricalFS!H27/HistoricalFS!H6,0) -> 0.04287197 | I18: =IFERROR(HistoricalFS!I27/HistoricalFS!I6,0) -> 0.045987202 | J18: =IFERROR(HistoricalFS!J27/HistoricalFS!J6,0) -> 0.056540247 | ... L18: =IFERROR(HistoricalFS!L27/HistoricalFS!L6,0) -> 0.0545658 | N18: =IFERROR(AVERAGE(C18:L18),0) -> 0.046724247 | O18: =IFERROR(MEDIAN(C18:L18),0) -> 0.044429586
B19: OperatingIncome%Sales | C19: =IFERROR(HistoricalFS!C25/HistoricalFS!C6,0) -> 0.14437382 | D19: =IFERROR(HistoricalFS!D25/HistoricalFS!D6,0) -> 0.14706913 | E19: =IFERROR(HistoricalFS!E25/HistoricalFS!E6,0) -> 0.12619625 | F19: =IFERROR(HistoricalFS!F25/HistoricalFS!F6,0) -> 0.1267566 | G19: =IFERROR(HistoricalFS!G25/HistoricalFS!G6,0) -> 0.16437669 | H19: =IFERROR(HistoricalFS!H25/HistoricalFS!H6,0) -> 0.14164794 | I19: =IFERROR(HistoricalFS!I25/HistoricalFS!I6,0) -> 0.13011812 | J19: =IFERROR(HistoricalFS!J25/HistoricalFS!J6,0) -> 0.14177106 | ... L19: =IFERROR(HistoricalFS!L25/HistoricalFS!L6,0) -> 0.1420926 | N19: =IFERROR(AVERAGE(C19:L19),0) -> 0.13997193 | O19: =IFERROR(MEDIAN(C19:L19),0) -> 0.1417095
B21: Return on Capital Employed | C21: =IFERROR(HistoricalFS!C25/SUM(HistoricalFS!C51:C53),0) -> 0.091197962 | D21: =IFERROR(HistoricalFS!D25/SUM(HistoricalFS!D51:D53),0) -> 0.10776808 | E21: =IFERROR(HistoricalFS!E25/SUM(HistoricalFS!E51:E53),0) -> 0.10322297 | F21: =IFERROR(HistoricalFS!F25/SUM(HistoricalFS!F51:F53),0) -> 0.094035924 | G21: =IFERROR(HistoricalFS!G25/SUM(HistoricalFS!G51:G53),0) -> 0.078283463 | H21: =IFERROR(HistoricalFS!H25/SUM(HistoricalFS!H51:H53),0) -> 0.089564126 | I21: =IFERROR(HistoricalFS!I25/SUM(HistoricalFS!I51:I53),0) -> 0.097671506 | J21: =IFERROR(HistoricalFS!J25/SUM(HistoricalFS!J51:J53),0) -> 0.11139486 | ... L21: =IFERROR(HistoricalFS!L25/SUM(HistoricalFS!L51:L53),0) -> 0.11537599 | N21: =IFERROR(AVERAGE(C21:L21),0) -> 0.099552483 | O21: =IFERROR(MEDIAN(C21:L21),0) -> 0.10044724
B22: Retained Earnings% | C22: =IFERROR(HistoricalFS!C47,0) -> 0.89089599 | D22: =IFERROR(HistoricalFS!D47,0) -> 0.90151885 | E22: =IFERROR(HistoricalFS!E47,0) -> 0.90330848 | F22: =IFERROR(HistoricalFS!F47,0) -> 0.89668129 | G22: =IFERROR(HistoricalFS!G47,0) -> 0.91604794 | H22: =IFERROR(HistoricalFS!H47,0) -> 0.92022994 | I22: =IFERROR(HistoricalFS!I47,0) -> 0.91780855 | J22: =IFERROR(HistoricalFS!J47,0) -> 0.9139547 | ... L22: =IFERROR(HistoricalFS!L47,0) -> 0.91508001 | N22: =IFERROR(AVERAGE(C22:L22),0) -> 0.90833995 | O22: =IFERROR(MEDIAN(C22:L22),0) -> 0.91091425
B23: Return on Equity% | C23: =IFERROR(HistoricalFS!C36/SUM(HistoricalFS!C51:C52),0) -> 0.11312849 | D23: =IFERROR(HistoricalFS!D36/SUM(HistoricalFS!D51:D52),0) -> 0.12292764 | E23: =IFERROR(HistoricalFS!E36/SUM(HistoricalFS!E51:E52),0) -> 0.1029082 | F23: =IFERROR(HistoricalFS!F36/SUM(HistoricalFS!F51:F52),0) -> 0.088786774 | G23: =IFERROR(HistoricalFS!G36/SUM(HistoricalFS!G51:G52),0) -> 0.076751141 | H23: =IFERROR(HistoricalFS!H36/SUM(HistoricalFS!H51:H52),0) -> 0.087038237 | I23: =IFERROR(HistoricalFS!I36/SUM(HistoricalFS!I51:I52),0) -> 0.10349336 | J23: =IFERROR(HistoricalFS!J36/SUM(HistoricalFS!J51:J52),0) -> 0.099098781 | ... L23: =IFERROR(HistoricalFS!L36/SUM(HistoricalFS!L51:L52),0) -> 0.10575976 | N23: =IFERROR(AVERAGE(C23:L23),0) -> 0.09957024 | O23: =IFERROR(MEDIAN(C23:L23),0) -> 0.10100349
B24: Self Sustained Growth Rate | C24: =IFERROR(C23*C22,0) -> 0.10078571 | D24: =IFERROR(D23*D22,0) -> 0.11082158 | E24: =IFERROR(E23*E22,0) -> 0.092957852 | F24: =IFERROR(F23*F22,0) -> 0.079613439 | G24: =IFERROR(G23*G22,0) -> 0.070307724 | H24: =IFERROR(H23*H22,0) -> 0.080095191 | I24: =IFERROR(I23*I22,0) -> 0.094987093 | J24: =IFERROR(J23*J22,0) -> 0.090571797 | ... L24: =IFERROR(L23*L22,0) -> 0.096778647 | N24: =IFERROR(AVERAGE(C24:L24),0) -> 0.090390244 | O24: =IFERROR(MEDIAN(C24:L24),0) -> 0.091764824
B25: Interest Coverage Ratio | C25: =IFERROR(HistoricalFS!C25/HistoricalFS!C22,0) -> 11.401143 | D25: =IFERROR(HistoricalFS!D25/HistoricalFS!D22,0) -> 7.1383507 | E25: =IFERROR(HistoricalFS!E25/HistoricalFS!E22,0) -> 4.3481055 | F25: =IFERROR(HistoricalFS!F25/HistoricalFS!F22,0) -> 3.4336496 | G25: =IFERROR(HistoricalFS!G25/HistoricalFS!G22,0) -> 3.617443 | H25: =IFERROR(HistoricalFS!H25/HistoricalFS!H22,0) -> 6.7470516 | I25: =IFERROR(HistoricalFS!I25/HistoricalFS!I22,0) -> 5.8267334 | J25: =IFERROR(HistoricalFS!J25/HistoricalFS!J22,0) -> 5.5133662 | ... L25: =IFERROR(HistoricalFS!L25/HistoricalFS!L22,0) -> 5.551273 | N25: =IFERROR(AVERAGE(C25:L25),0) -> 5.8945529 | O25: =IFERROR(MEDIAN(C25:L25),0) -> 5.5323196
B27: Debtor Turnover Ratio | C27: =HistoricalFS!C6/HistoricalFS!C63 -> 37.171823 | D27: =HistoricalFS!D6/HistoricalFS!D63 -> 22.262774 | E27: =HistoricalFS!E6/HistoricalFS!E63 -> 18.888531 | F27: =HistoricalFS!F6/HistoricalFS!F63 -> 30.356074 | G27: =HistoricalFS!G6/HistoricalFS!G63 -> 24.524403 | H27: =HistoricalFS!H6/HistoricalFS!H63 -> 29.385491 | I27: =HistoricalFS!I6/HistoricalFS!I63 -> 30.806946 | J27: =HistoricalFS!J6/HistoricalFS!J63 -> 28.425477 | ... L27: =HistoricalFS!L6/HistoricalFS!L63 -> 18.0749 | N27: =IFERROR(AVERAGE(C27:L27),0) -> 26.275485 | O27: =IFERROR(MEDIAN(C27:L27),0) -> 26.47494
B28: Creditor Turnover Ratio | C28: =HistoricalFS!C6/HistoricalFS!C54 -> 1.3472063 | D28: =HistoricalFS!D6/HistoricalFS!D54 -> 1.4062226 | E28: =HistoricalFS!E6/HistoricalFS!E54 -> 1.8769138 | F28: =HistoricalFS!F6/HistoricalFS!F54 -> 1.6633744 | G28: =HistoricalFS!G6/HistoricalFS!G54 -> 1.367746 | H28: =HistoricalFS!H6/HistoricalFS!H54 -> 1.7367737 | I28: =HistoricalFS!I6/HistoricalFS!I54 -> 1.9993247 | J28: =HistoricalFS!J6/HistoricalFS!J54 -> 1.4717917 | ... L28: =HistoricalFS!L6/HistoricalFS!L54 -> 1.2067195 | N28: =IFERROR(AVERAGE(C28:L28),0) -> 1.5391041 | O28: =IFERROR(MEDIAN(C28:L28),0) -> 1.4390071
B29: Inventory Turnober Ratio | C29: =HistoricalFS!C10/HistoricalFS!C64 -> 4.9406141 | D29: =HistoricalFS!D10/HistoricalFS!D64 -> 4.9517399 | E29: =HistoricalFS!E10/HistoricalFS!E64 -> 6.4564172 | F29: =HistoricalFS!F10/HistoricalFS!F64 -> 6.0328674 | G29: =HistoricalFS!G10/HistoricalFS!G64 -> 4.0211945 | H29: =HistoricalFS!H10/HistoricalFS!H64 -> 4.8416746 | I29: =HistoricalFS!I10/HistoricalFS!I64 -> 4.7002671 | J29: =HistoricalFS!J10/HistoricalFS!J64 -> 4.2641553 | ... L29: =HistoricalFS!L10/HistoricalFS!L64 -> 4.306797 | N29: =IFERROR(AVERAGE(C29:L29),0) -> 4.931115 | O29: =IFERROR(MEDIAN(C29:L29),0) -> 4.8185485
B30: Fixed Asset Turnover Ratio | C30: =HistoricalFS!C6/HistoricalFS!C57 -> 1.5310539 | D30: =HistoricalFS!D6/HistoricalFS!D57 -> 0.96765911 | E30: =HistoricalFS!E6/HistoricalFS!E57 -> 1.4266418 | F30: =HistoricalFS!F6/HistoricalFS!F57 -> 1.1201916 | G30: =HistoricalFS!G6/HistoricalFS!G57 -> 0.86152445 | H30: =HistoricalFS!H6/HistoricalFS!H57 -> 1.1065231 | I30: =HistoricalFS!I6/HistoricalFS!I57 -> 1.2091473 | J30: =HistoricalFS!J6/HistoricalFS!J57 -> 1.1526388 | ... L30: =HistoricalFS!L6/HistoricalFS!L57 -> 0.90345618 | N30: =IFERROR(AVERAGE(C30:L30),0) -> 1.1242241 | O30: =IFERROR(MEDIAN(C30:L30),0) -> 1.1133573
B31: Capital Turnover Ratio | C31: =HistoricalFS!C6/SUM(HistoricalFS!C51,HistoricalFS!C52) -> 1.1526114 | D31: =HistoricalFS!D6/SUM(HistoricalFS!D51,HistoricalFS!D52) -> 1.3315673 | E31: =HistoricalFS!E6/SUM(HistoricalFS!E51,HistoricalFS!E52) -> 1.4681462 | F31: =HistoricalFS!F6/SUM(HistoricalFS!F51,HistoricalFS!F52) -> 1.3284153 | G31: =HistoricalFS!G6/SUM(HistoricalFS!G51,HistoricalFS!G52) -> 0.66598921 | H31: =HistoricalFS!H6/SUM(HistoricalFS!H51,HistoricalFS!H52) -> 0.89119483 | I31: =HistoricalFS!I6/SUM(HistoricalFS!I51,HistoricalFS!I52) -> 1.2242356 | J31: =HistoricalFS!J6/SUM(HistoricalFS!J51,HistoricalFS!J52) -> 1.1330341 | ... L31: =HistoricalFS!L6/SUM(HistoricalFS!L51,HistoricalFS!L52) -> 1.1694512 | N31: =IFERROR(AVERAGE(C31:L31),0) -> 1.150651 | O31: =IFERROR(MEDIAN(C31:L31),0) -> 1.1610313
B34: Debtor Days | C34: =IFERROR(365/C27,0) -> 9.8192654 | D34: =IFERROR(365/D27,0) -> 16.395082 | E34: =IFERROR(365/E27,0) -> 19.323896 | F34: =IFERROR(365/F27,0) -> 12.023953 | G34: =IFERROR(365/G27,0) -> 14.883135 | H34: =IFERROR(365/H27,0) -> 12.421096 | I34: =IFERROR(365/I27,0) -> 11.847977 | J34: =IFERROR(365/J27,0) -> 12.840593 | ... L34: =IFERROR(365/L27,0) -> 20.193749 | N34: =IFERROR(AVERAGE(C34:L34),0) -> 14.57166 | O34: =IFERROR(MEDIAN(C34:L34),0) -> 13.861864
B35: Payable Days | C35: =IFERROR(365/C28,0) -> 270.93103 | D35: =IFERROR(365/D28,0) -> 259.56062 | E35: =IFERROR(365/E28,0) -> 194.46818 | F35: =IFERROR(365/F28,0) -> 219.43346 | G35: =IFERROR(365/G28,0) -> 266.86242 | H35: =IFERROR(365/H28,0) -> 210.15979 | I35: =IFERROR(365/I28,0) -> 182.56164 | J35: =IFERROR(365/J28,0) -> 247.99705 | ... L35: =IFERROR(365/L28,0) -> 302.47295 | N35: =IFERROR(AVERAGE(C35:L35),0) -> 243.20203 | O35: =IFERROR(MEDIAN(C35:L35),0) -> 253.77884
B36: Inventory Days | C36: =IFERROR(365/C29,0) -> 73.877456 | D36: =IFERROR(365/D29,0) -> 73.711465 | E36: =IFERROR(365/E29,0) -> 56.532902 | F36: =IFERROR(365/F29,0) -> 60.50191 | G36: =IFERROR(365/G29,0) -> 90.769048 | H36: =IFERROR(365/H29,0) -> 75.387141 | I36: =IFERROR(365/I29,0) -> 77.655161 | J36: =IFERROR(365/J29,0) -> 85.597258 | ... L36: =IFERROR(365/L29,0) -> 84.749757 | N36: =IFERROR(AVERAGE(C36:L36),0) -> 75.489635 | O36: =IFERROR(MEDIAN(C36:L36),0) -> 75.750697
B37: Cash Conversion Cycle | C37: =SUM(C34,C36)-C35 -> -187.23431 | D37: =SUM(D34,D36)-D35 -> -169.45407 | E37: =SUM(E34,E36)-E35 -> -118.61138 | F37: =SUM(F34,F36)-F35 -> -146.9076 | G37: =SUM(G34,G36)-G35 -> -161.21024 | H37: =SUM(H34,H36)-H35 -> -122.35156 | I37: =SUM(I34,I36)-I35 -> -93.058501 | J37: =SUM(J34,J36)-J35 -> -149.5592 | ... L37: =SUM(L34,L36)-L35 -> -197.52944 | N37: =IFERROR(AVERAGE(C37:L37),0) -> -153.14074 | O37: =IFERROR(MEDIAN(C37:L37),0) -> -155.38472
B39: CFO/Sales | C39: =IFERROR(HistoricalFS!C81/HistoricalFS!C6,0) -> 0.15121696 | D39: =IFERROR(HistoricalFS!D81/HistoricalFS!D6,0) -> 0.16634896 | E39: =IFERROR(HistoricalFS!E81/HistoricalFS!E6,0) -> 0.15835147 | F39: =IFERROR(HistoricalFS!F81/HistoricalFS!F6,0) -> 0.022732491 | G39: =IFERROR(HistoricalFS!G81/HistoricalFS!G6,0) -> 0.24188571 | H39: =IFERROR(HistoricalFS!H81/HistoricalFS!H6,0) -> -0.033109103 | I39: =IFERROR(HistoricalFS!I81/HistoricalFS!I6,0) -> 0.12708753 | J39: =IFERROR(HistoricalFS!J81/HistoricalFS!J6,0) -> 0.10611084 | ... L39: =IFERROR(HistoricalFS!L81/HistoricalFS!L6,0) -> 0.19147121 | N39: =IFERROR(AVERAGE(C39:L39),0) -> 0.13036276 | O39: =IFERROR(MEDIAN(C39:L39),0) -> 0.15478422
B40: CFO/Total Assets | C40: =IFERROR(HistoricalFS!C81/HistoricalFS!C68,0) -> 0.065029527 | D40: =IFERROR(HistoricalFS!D81/HistoricalFS!D68,0) -> 0.080137019 | E40: =IFERROR(HistoricalFS!E81/HistoricalFS!E68,0) -> 0.0902108 | F40: =IFERROR(HistoricalFS!F81/HistoricalFS!F68,0) -> 0.01166279 | G40: =IFERROR(HistoricalFS!G81/HistoricalFS!G68,0) -> 0.085445035 | H40: =IFERROR(HistoricalFS!H81/HistoricalFS!H68,0) -> -0.015347433 | I40: =IFERROR(HistoricalFS!I81/HistoricalFS!I68,0) -> 0.069356902 | J40: =IFERROR(HistoricalFS!J81/HistoricalFS!J68,0) -> 0.054356348 | ... L40: =IFERROR(HistoricalFS!L81/HistoricalFS!L68,0) -> 0.092935716 | N40: =IFERROR(AVERAGE(C40:L40),0) -> 0.061849353 | O40: =IFERROR(MEDIAN(C40:L40),0) -> 0.07474696
B41: CFO/Total Debts | C41: =IFERROR(HistoricalFS!C81/HistoricalFS!C53,0) -> 0.21134843 | D41: =IFERROR(HistoricalFS!D81/HistoricalFS!D53,0) -> 0.27106482 | E41: =IFERROR(HistoricalFS!E81/HistoricalFS!E53,0) -> 0.29246963 | F41: =IFERROR(HistoricalFS!F81/HistoricalFS!F53,0) -> 0.038194141 | G41: =IFERROR(HistoricalFS!G81/HistoricalFS!G53,0) -> 0.40433106 | H41: =IFERROR(HistoricalFS!H81/HistoricalFS!H53,0) -> -0.07206462 | I41: =IFERROR(HistoricalFS!I81/HistoricalFS!I53,0) -> 0.24659703 | J41: =IFERROR(HistoricalFS!J81/HistoricalFS!J53,0) -> 0.27200693 | ... L41: =IFERROR(HistoricalFS!L81/HistoricalFS!L53,0) -> 0.50861055 | N41: =IFERROR(AVERAGE(C41:L41),0) -> 0.2613777 | O41: =IFERROR(MEDIAN(C41:L41),0) -> 0.27153588

Sheet HistoricalFS
A2: # | B2: ="Historical Financial Statements "&'Data Sheet'!B1 -> Historical Financial Statements RELIANCE INDUSTRIES LTD
B3: Years | C3: ='Data Sheet'!B16 -> 42825 | D3: ='Data Sheet'!C16 -> 43190 | E3: ='Data Sheet'!D16 -> 43555 | F3: ='Data Sheet'!E16 -> 43921 | G3: ='Data Sheet'!F16 -> 44286 | H3: ='Data Sheet'!G16 -> 44651 | I3: ='Data Sheet'!H16 -> 45016 | J3: ='Data Sheet'!I16 -> 45382 | ... L3: ='Data Sheet'!K16 -> 46112 | M3: LTM
B5: Income Statement
B6: Sales | C6: =IFERROR('Data Sheet'!B17,0) -> 303954 | D6: =IFERROR('Data Sheet'!C17,0) -> 390823 | E6: =IFERROR('Data Sheet'!D17,0) -> 568337 | F6: =IFERROR('Data Sheet'!E17,0) -> 596679 | G6: =IFERROR('Data Sheet'!F17,0) -> 466307 | H6: =IFERROR('Data Sheet'!G17,0) -> 694673 | I6: =IFERROR('Data Sheet'!H17,0) -> 876396 | J6: =IFERROR('Data Sheet'!I17,0) -> 899041 | ... L6: =IFERROR('Data Sheet'!K17,0) -> 1057219 | M6: {=IFERROR(SUM('Data Sheet'!H42:K42),O0)} -> 1057219
B7: Other Income | C7: =IFERROR('Data Sheet'!B25,0) -> 9222 | D7: =IFERROR('Data Sheet'!C25,0) -> 9869 | E7: =IFERROR('Data Sheet'!D25,0) -> 8406 | F7: =IFERROR('Data Sheet'!E25,0) -> 8570 | G7: =IFERROR('Data Sheet'!F25,0) -> 22432 | H7: =IFERROR('Data Sheet'!G25,0) -> 19600 | I7: =IFERROR('Data Sheet'!H25,0) -> 12020 | J7: =IFERROR('Data Sheet'!I25,0) -> 15792 | ... L7: =IFERROR('Data Sheet'!K25,0) -> 28962
B8: Sales Growth | C8: - | D8: =D6/C6-1 -> 0.28579654 | E8: =E6/D6-1 -> 0.45420561 | F8: =F6/E6-1 -> 0.0498683 | G8: =G6/F6-1 -> -0.21849604 | H8: =H6/G6-1 -> 0.48973316 | I8: =I6/H6-1 -> 0.26159502 | J8: =J6/I6-1 -> 0.025838776 | K8: =K6/J6-1 -> 0.070941147 | L8: =L6/K6-1 -> 0.098044287
B10: COGS | C10: =IFERROR(SUM('Data Sheet'!B18,'Data Sheet'!B20:B22)-1*'Data Sheet'!B19,0) -> 241848 | D10: =IFERROR(SUM('Data Sheet'!C18,'Data Sheet'!C20:C22)-1*'Data Sheet'!C19,0) -> 301249 | E10: =IFERROR(SUM('Data Sheet'!D18,'Data Sheet'!D20:D22)-1*'Data Sheet'!D19,0) -> 436202 | F10: =IFERROR(SUM('Data Sheet'!E18,'Data Sheet'!E20:E22)-1*'Data Sheet'!E19,0) -> 445847 | G10: =IFERROR(SUM('Data Sheet'!F18,'Data Sheet'!F20:F22)-1*'Data Sheet'!F19,0) -> 328419 | H10: =IFERROR(SUM('Data Sheet'!G18,'Data Sheet'!G20:G22)-1*'Data Sheet'!G19,0) -> 521826 | I10: =IFERROR(SUM('Data Sheet'!H18,'Data Sheet'!H20:H22)-1*'Data Sheet'!H19,0) -> 658075 | J10: =IFERROR(SUM('Data Sheet'!I18,'Data Sheet'!I20:I22)-1*'Data Sheet'!I19,0) -> 651435 | ... L10: =IFERROR(SUM('Data Sheet'!K18,'Data Sheet'!K20:K22)-1*'Data Sheet'!K19,0) -> 718981 | M10: =IFERROR(SUM('Data Sheet'!H43:K43),0) -> 878270
B11: COGS % Sales | C11: =C10/C6 -> 0.79567303 | D11: =D10/D6 -> 0.77080673 | E11: =E10/E6 -> 0.7675059 | F11: =F10/F6 -> 0.74721416 | G11: =G10/G6 -> 0.70429781 | H11: =H10/H6 -> 0.75118221 | I11: =I10/I6 -> 0.75088773 | J11: =J10/J6 -> 0.72458876 | ... L11: =L10/L6 -> 0.68006818
B13: Gross Profit | C13: =SUM(HistoricalFS!C6,C7)-C10 -> 71328 | D13: =SUM(HistoricalFS!D6,D7)-D10 -> 99443 | E13: =SUM(HistoricalFS!E6,E7)-E10 -> 140541 | F13: =SUM(HistoricalFS!F6,F7)-F10 -> 159402 | G13: =SUM(HistoricalFS!G6,G7)-G10 -> 160320 | H13: =SUM(HistoricalFS!H6,H7)-H10 -> 192447 | I13: =SUM(HistoricalFS!I6,I7)-I10 -> 230341 | J13: =SUM(HistoricalFS!J6,J7)-J10 -> 263398 | ... L13: =SUM(HistoricalFS!L6,L7)-L10 -> 367200 | M13: =HistoricalFS!M6-HistoricalFS!M10 -> 178949
B14: Gross Margin | C14: =IFERROR(C13/C6,0) -> 0.23466709 | D14: =IFERROR(D13/D6,0) -> 0.25444511 | E14: =IFERROR(E13/E6,0) -> 0.24728462 | F14: =IFERROR(F13/F6,0) -> 0.26714867 | G14: =IFERROR(G13/G6,0) -> 0.34380783 | H14: =IFERROR(H13/H6,0) -> 0.2770325 | I14: =IFERROR(I13/I6,0) -> 0.26282753 | J14: =IFERROR(J13/J6,0) -> 0.29297663 | ... L14: =IFERROR(L13/L6,0) -> 0.34732633
B16: Selling & General Expenses | C16: =IFERROR(SUM('Data Sheet'!B23:B24),0) -> 15799 | D16: =IFERROR(SUM('Data Sheet'!C23:C24),0) -> 25259 | E16: =IFERROR(SUM('Data Sheet'!D23:D24),0) -> 47885 | F16: =IFERROR(SUM('Data Sheet'!E23:E24),0) -> 61566 | G16: =IFERROR(SUM('Data Sheet'!F23:F24),0) -> 57098 | H16: =IFERROR(SUM('Data Sheet'!G23:G24),0) -> 64266 | I16: =IFERROR(SUM('Data Sheet'!H23:H24),0) -> 76003 | J16: =IFERROR(SUM('Data Sheet'!I23:I24),0) -> 85108 | ... L16: =IFERROR(SUM('Data Sheet'!K23:K24),0) -> 159289
B17: S&G Exp % Sales | C17: =C16/C6 -> 0.05197826 | D17: =D16/D6 -> 0.06463028 | E17: =E16/E6 -> 0.084254588 | F17: =F16/F6 -> 0.10318111 | G17: =G16/G6 -> 0.12244723 | H17: =H16/H6 -> 0.092512592 | I17: =I16/I6 -> 0.086722212 | J17: =J16/J6 -> 0.094665316 | ... L17: =L16/L6 -> 0.15066793
B19: EBITDA | C19: =C13-C16 -> 55529 | D19: =D13-D16 -> 74184 | E19: =E13-E16 -> 92656 | F19: =F13-F16 -> 97836 | G19: =G13-G16 -> 103222 | H19: =H13-H16 -> 128181 | I19: =I13-I16 -> 154338 | J19: =J13-J16 -> 178290 | ... L19: =L13-L16 -> 207911
B20: EBITDA Margins | C20: =C19/C6 -> 0.18268883 | D20: =D19/D6 -> 0.18981483 | E20: =E19/E6 -> 0.16303003 | F20: =F19/F6 -> 0.16396756 | G20: =G19/G6 -> 0.22136061 | H20: =H19/H6 -> 0.18451991 | I20: =I19/I6 -> 0.17610532 | J20: =J19/J6 -> 0.19831131 | ... L20: =L19/L6 -> 0.1966584
B22: Interest | C22: {=IFERROR('Data Sheet'!B27:K27,0)} -> 3849 | D22: 8052 | E22: 16495 | F22: 22027 | G22: 21189 | H22: 14584 | I22: 19571 | J22: 23118 | K22: 24269 | L22: 27061 | M22: =IFERROR(SUM('Data Sheet'!H46:K46),0) -> 27061
B23: Interest % Sales | C23: =C22/C6 -> 0.0126631 | D23: =D22/D6 -> 0.020602677 | E23: =E22/E6 -> 0.029023273 | F23: =F22/F6 -> 0.036915997 | G23: =G22/G6 -> 0.045440021 | H23: =H22/H6 -> 0.02099405 | I23: =I22/I6 -> 0.022331229 | J23: =J22/J6 -> 0.025714066 | ... M23: =M22/M6 -> 0.0255964
B25: EBIT | C25: =IFERROR(C19-C27,0) -> 43883 | D25: =IFERROR(D19-D27,0) -> 57478 | E25: =IFERROR(E19-E27,0) -> 71722 | F25: =IFERROR(F19-F27,0) -> 75633 | G25: =IFERROR(G19-G27,0) -> 76650 | H25: =IFERROR(H19-H27,0) -> 98399 | I25: =IFERROR(I19-I27,0) -> 114035 | J25: =IFERROR(J19-J27,0) -> 127458 | ... L25: =IFERROR(L19-L27,0) -> 150223
B27: Depreciation | C27: =IFERROR('Data Sheet'!B26,0) -> 11646 | D27: =IFERROR('Data Sheet'!C26,0) -> 16706 | E27: =IFERROR('Data Sheet'!D26,0) -> 20934 | F27: =IFERROR('Data Sheet'!E26,0) -> 22203 | G27: =IFERROR('Data Sheet'!F26,0) -> 26572 | H27: =IFERROR('Data Sheet'!G26,0) -> 29782 | I27: =IFERROR('Data Sheet'!H26,0) -> 40303 | J27: =IFERROR('Data Sheet'!I26,0) -> 50832 | ... L27: =IFERROR('Data Sheet'!K26,0) -> 57688 | M27: =IFERROR(SUM('Data Sheet'!H45:K45),0) -> 57688
B28: Depreciation % Sales | C28: =C27/C6 -> 0.038315008 | D28: =D27/D6 -> 0.042745693 | E28: =E27/E6 -> 0.03683378 | F28: =F27/F6 -> 0.037210963 | G28: =G27/G6 -> 0.056983918 | H28: =H27/H6 -> 0.04287197 | I28: =I27/I6 -> 0.045987202 | J28: =J27/J6 -> 0.056540247 | ... M28: =M27/M6 -> 0.0545658
B30: Earnings Before Tax | C30: =IFERROR('Data Sheet'!B28,0) -> 40034 | D30: =IFERROR('Data Sheet'!C28,0) -> 49426 | E30: =IFERROR('Data Sheet'!D28,0) -> 55227 | F30: =IFERROR('Data Sheet'!E28,0) -> 53606 | G30: =IFERROR('Data Sheet'!F28,0) -> 55461 | H30: =IFERROR('Data Sheet'!G28,0) -> 83815 | I30: =IFERROR('Data Sheet'!H28,0) -> 94464 | J30: =IFERROR('Data Sheet'!I28,0) -> 104340 | ... L30: =IFERROR('Data Sheet'!K28,0) -> 123162 | M30: =IFERROR(SUM('Data Sheet'!H47:K47),0) -> 123162
B31: EBT % Sales | C31: =C30/C6 -> 0.13171072 | D31: =D30/D6 -> 0.12646646 | E31: =E30/E6 -> 0.09717298 | F31: =F30/F6 -> 0.089840601 | G31: =G30/G6 -> 0.11893667 | H31: =H30/H6 -> 0.12065389 | I31: =I30/I6 -> 0.10778689 | J31: =J30/J6 -> 0.116057 | ... M31: =M30/M6 -> 0.1164962
B33: Tax | C33: =IFERROR('Data Sheet'!B29,0) -> 10201 | D33: =IFERROR('Data Sheet'!C29,0) -> 13346 | E33: =IFERROR('Data Sheet'!D29,0) -> 15390 | F33: =IFERROR('Data Sheet'!E29,0) -> 13726 | G33: =IFERROR('Data Sheet'!F29,0) -> 1722 | H33: =IFERROR('Data Sheet'!G29,0) -> 15970 | I33: =IFERROR('Data Sheet'!H29,0) -> 20376 | J33: =IFERROR('Data Sheet'!I29,0) -> 25707 | ... L33: =IFERROR('Data Sheet'!K29,0) -> 27552
B34: Effective Tac Rate | C34: =C33/C19 -> 0.18370581 | D34: =D33/D19 -> 0.17990402 | E34: =E33/E19 -> 0.16609826 | F34: =F33/F19 -> 0.14029601 | G34: =G33/G19 -> 0.01668249 | H34: =H33/H19 -> 0.12458945 | I34: =I33/I19 -> 0.13202193 | J34: =J33/J19 -> 0.14418644 | ... L34: =L33/L19 -> 0.13251824
B36: Net Profit | C36: =C30-C33 -> 29833 | D36: =D30-D33 -> 36080 | E36: =E30-E33 -> 39837 | F36: =F30-F33 -> 39880 | G36: =G30-G33 -> 53739 | H36: =H30-H33 -> 67845 | I36: =I30-I33 -> 74088 | J36: =J30-J33 -> 78633 | ... M36: =M30-M33 -> 123162
B37: Net Margins | C37: =C36/C6 -> 0.09814972 | D37: =D36/D6 -> 0.092318006 | E37: =E36/E6 -> 0.070093976 | F37: =F36/F6 -> 0.066836607 | G37: =G36/G6 -> 0.11524382 | H37: =H36/H6 -> 0.097664657 | I37: =I36/I6 -> 0.084537127 | J37: =J36/J6 -> 0.087463197 | ... M37: =M36/M6 -> 0.1164962
B39: No of Equity Shares | C39: =IFERROR('Data Sheet'!B93,0) -> 1387.22 | D39: =IFERROR('Data Sheet'!C93,0) -> 1351.39 | E39: =IFERROR('Data Sheet'!D93,0) -> 1352.26 | F39: =IFERROR('Data Sheet'!E93,0) -> 1352.37 | G39: =IFERROR('Data Sheet'!F93,0) -> 1267.89 | H39: =IFERROR('Data Sheet'!G93,0) -> 1352.98 | I39: =IFERROR('Data Sheet'!H93,0) -> 1353.12 | J39: =IFERROR('Data Sheet'!I93,0) -> 1353.14 | ... L39: =IFERROR('Data Sheet'!K93,0) -> 1353.25
B41: EPS | C41: =IFERROR(C36/C39,0) -> 21.505601 | D41: =IFERROR(D36/D39,0) -> 26.698436 | E41: =IFERROR(E36/E39,0) -> 29.459571 | F41: =IFERROR(F36/F39,0) -> 29.488971 | G41: =IFERROR(G36/G39,0) -> 42.384592 | H41: =IFERROR(H36/H39,0) -> 50.144865 | I41: =IFERROR(I36/I39,0) -> 54.753459 | J41: =IFERROR(J36/J39,0) -> 58.111504 | ... M41: =IFERROR(M36/M39,0) -> 0
B42: EPS Growth % | D42: =IFERROR(D41/C41-1,0) -> 0.24146432 | E42: =IFERROR(E41/D41-1,0) -> 0.10341935 | F42: =IFERROR(F41/E41-1,0) -> 0.00099797207 | G42: =IFERROR(G41/F41-1,0) -> 0.43730317 | H42: =IFERROR(H41/G41-1,0) -> 0.18309186 | I42: =IFERROR(I41/H41-1,0) -> 0.091905586 | J42: =IFERROR(J41/I41-1,0) -> 0.06133028 | K42: =IFERROR(K41/J41-1,0) -> 0.027317158 | L42: =IFERROR(L41/K41-1,0) -> 0.18347375
B44: Dividend per Share | C44: =IFERROR('Data Sheet'!B31/C39,0) -> 2.3463474 | D44: =IFERROR('Data Sheet'!C31/D39,0) -> 2.6292928 | E44: =IFERROR('Data Sheet'!D31/E39,0) -> 2.8484907 | F44: =IFERROR('Data Sheet'!E31/F39,0) -> 3.0467624 | G44: =IFERROR('Data Sheet'!F31/G39,0) -> 3.558274 | H44: =IFERROR('Data Sheet'!G31/H39,0) -> 4.0000591 | I44: =IFERROR('Data Sheet'!H31/I39,0) -> 4.5002661 | J44: =IFERROR('Data Sheet'!I31/J39,0) -> 5.0002217 | ... M44: =IFERROR('Data Sheet'!L31/M39,0) -> 0
B45: Dividend Payout Ratio | C45: =IFERROR(C44/C41,0) -> 0.10910401 | D45: =IFERROR(D44/D41,0) -> 0.098481153 | E45: =IFERROR(E44/E41,0) -> 0.096691518 | F45: =IFERROR(F44/F41,0) -> 0.10331871 | G45: =IFERROR(G44/G41,0) -> 0.083952065 | H45: =IFERROR(H44/H41,0) -> 0.079770064 | I45: =IFERROR(I44/I41,0) -> 0.082191448 | J45: =IFERROR(J44/J41,0) -> 0.086045299 | ... L45: =IFERROR(L44/L41,0) -> 0.084919987
B47: Retained Earnings | C47: =IFERROR(1-C45,0) -> 0.89089599 | D47: =IFERROR(1-D45,0) -> 0.90151885 | E47: =IFERROR(1-E45,0) -> 0.90330848 | F47: =IFERROR(1-F45,0) -> 0.89668129 | G47: =IFERROR(1-G45,0) -> 0.91604794 | H47: =IFERROR(1-H45,0) -> 0.92022994 | I47: =IFERROR(1-I45,0) -> 0.91780855 | J47: =IFERROR(1-J45,0) -> 0.9139547 | ... M47: =IFERROR(1-M45,0) -> 1
B50: Balance Sheet
B51: Equity Share Capital | C51: =IFERROR('Data Sheet'!B57,0) -> 2959 | D51: =IFERROR('Data Sheet'!C57,0) -> 5922 | E51: =IFERROR('Data Sheet'!D57,0) -> 5926 | F51: =IFERROR('Data Sheet'!E57,0) -> 6339 | G51: =IFERROR('Data Sheet'!F57,0) -> 6445 | H51: =IFERROR('Data Sheet'!G57,0) -> 6765 | I51: =IFERROR('Data Sheet'!H57,0) -> 6766 | J51: =IFERROR('Data Sheet'!I57,0) -> 6766 | ... M51: =IFERROR('Data Sheet'!L57,0) -> 0
B52: Reserves | C52: {=IFERROR('Data Sheet'!B58:B61,0)} -> 260750 | D52: {=IFERROR('Data Sheet'!C58:C61,0)} -> 287584 | E52: {=IFERROR('Data Sheet'!D58:D61,0)} -> 381186 | F52: {=IFERROR('Data Sheet'!E58:E61,0)} -> 442827 | G52: {=IFERROR('Data Sheet'!F58:F61,0)} -> 693727 | H52: {=IFERROR('Data Sheet'!G58:G61,0)} -> 772720 | I52: {=IFERROR('Data Sheet'!H58:H61,0)} -> 709106 | J52: {=IFERROR('Data Sheet'!I58:I61,0)} -> 786715 | ... M52: {=IFERROR('Data Sheet'!L58:L61,0)} -> 0
B53: Borrowings | C53: 217475 | D53: 239843 | E53: 307714 | F53: 355133 | G53: 278962 | H53: 319158 | I53: 451664 | J53: 350719 | K53: 374313 | L53: 398000 | M53: 0
B54: Other Liabilities | C54: 225618 | D54: 277924 | E54: 302804 | F54: 358716 | G54: 340931 | H54: 399979 | I54: 438346 | J54: 610848 | K54: 732200 | L54: 876110 | M54: 0
B55: Total Liabilities | C55: 706802 | D55: 811273 | E55: 997630 | F55: 1163015 | G55: 1320065 | H55: 1498622 | I55: 1605882 | J55: 1755048 | K55: 1949713 | L55: 2178140 | M55: 0
B57: Fixed Assests Net Block | C57: =IFERROR('Data Sheet'!B62,0) -> 198526 | D57: =IFERROR('Data Sheet'!C62,0) -> 403885 | E57: =IFERROR('Data Sheet'!D62,0) -> 398374 | F57: =IFERROR('Data Sheet'!E62,0) -> 532658 | G57: =IFERROR('Data Sheet'!F62,0) -> 541258 | H57: =IFERROR('Data Sheet'!G62,0) -> 627798 | I57: =IFERROR('Data Sheet'!H62,0) -> 724805 | J57: =IFERROR('Data Sheet'!I62,0) -> 779985 | ... M57: =IFERROR('Data Sheet'!L62,0) -> 0
B58: Capital Work in Progress | C58: =IFERROR('Data Sheet'!B63,0) -> 324837 | D58: =IFERROR('Data Sheet'!C63,0) -> 187022 | E58: =IFERROR('Data Sheet'!D63,0) -> 179463 | F58: =IFERROR('Data Sheet'!E63,0) -> 109106 | G58: =IFERROR('Data Sheet'!F63,0) -> 125953 | H58: =IFERROR('Data Sheet'!G63,0) -> 172506 | I58: =IFERROR('Data Sheet'!H63,0) -> 293752 | J58: =IFERROR('Data Sheet'!I63,0) -> 338855 | ... M58: =IFERROR('Data Sheet'!L63,0) -> 0
B59: Investments | C59: =IFERROR('Data Sheet'!B64,0) -> 82899 | D59: =IFERROR('Data Sheet'!C64,0) -> 82862 | E59: =IFERROR('Data Sheet'!D64,0) -> 235635 | F59: =IFERROR('Data Sheet'!E64,0) -> 276767 | G59: =IFERROR('Data Sheet'!F64,0) -> 364828 | H59: =IFERROR('Data Sheet'!G64,0) -> 394264 | I59: =IFERROR('Data Sheet'!H64,0) -> 235560 | J59: =IFERROR('Data Sheet'!I64,0) -> 225672 | ... M59: =IFERROR('Data Sheet'!L64,0) -> 0
...

Sheet Common Size
B2: ="Common Size Income Statement"&""&"-"&'Data Sheet'!B1 -> Common Size Income Statement-RELIANCE INDUSTRIES LTD
B4: Particulars | C4: =IFERROR('Data Sheet'!B16,0) -> 42825 | D4: =IFERROR('Data Sheet'!C16,0) -> 43190 | E4: =IFERROR('Data Sheet'!D16,0) -> 43555 | F4: =IFERROR('Data Sheet'!E16,0) -> 43921 | G4: =IFERROR('Data Sheet'!F16,0) -> 44286 | H4: =IFERROR('Data Sheet'!G16,0) -> 44651 | I4: =IFERROR('Data Sheet'!H16,0) -> 45016 | J4: =IFERROR('Data Sheet'!I16,0) -> 45382 | ... L4: =IFERROR('Data Sheet'!K16,0) -> 46112
B5: Sales | C5: =IFERROR('Data Sheet'!B17/'Data Sheet'!B$17,0) -> 1 | D5: =IFERROR('Data Sheet'!C17/'Data Sheet'!C$17,0) -> 1 | E5: =IFERROR('Data Sheet'!D17/'Data Sheet'!D$17,0) -> 1 | F5: =IFERROR('Data Sheet'!E17/'Data Sheet'!E$17,0) -> 1 | G5: =IFERROR('Data Sheet'!F17/'Data Sheet'!F$17,0) -> 1 | H5: =IFERROR('Data Sheet'!G17/'Data Sheet'!G$17,0) -> 1 | I5: =IFERROR('Data Sheet'!H17/'Data Sheet'!H$17,0) -> 1 | J5: =IFERROR('Data Sheet'!I17/'Data Sheet'!I$17,0) -> 1 | ... L5: =IFERROR('Data Sheet'!K17/'Data Sheet'!K$17,0) -> 1
B6: Raw Material Cost | C6: =IFERROR('Data Sheet'!B18/'Data Sheet'!B$17,0) -> 0.71562802 | D6: =IFERROR('Data Sheet'!C18/'Data Sheet'!C$17,0) -> 0.7063965 | E6: =IFERROR('Data Sheet'!D18/'Data Sheet'!D$17,0) -> 0.7023421 | F6: =IFERROR('Data Sheet'!E18/'Data Sheet'!E$17,0) -> 0.68761931 | G6: =IFERROR('Data Sheet'!F18/'Data Sheet'!F$17,0) -> 0.64713804 | H6: =IFERROR('Data Sheet'!G18/'Data Sheet'!G$17,0) -> 0.7117723 | I6: =IFERROR('Data Sheet'!H18/'Data Sheet'!H$17,0) -> 0.70601189 | J6: =IFERROR('Data Sheet'!I18/'Data Sheet'!I$17,0) -> 0.65650621 | ... L6: =IFERROR('Data Sheet'!K18/'Data Sheet'!K$17,0) -> 0.66110238
B7: Change in Inventory | C7: =IFERROR('Data Sheet'!B19/'Data Sheet'!B$17,0) -> 0.017167071 | D7: =IFERROR('Data Sheet'!C19/'Data Sheet'!C$17,0) -> 0.022030433 | E7: =IFERROR('Data Sheet'!D19/'Data Sheet'!D$17,0) -> 0.008234551 | F7: =IFERROR('Data Sheet'!E19/'Data Sheet'!E$17,0) -> 0.0084601603 | G7: =IFERROR('Data Sheet'!F19/'Data Sheet'!F$17,0) -> 0.019437838 | H7: =IFERROR('Data Sheet'!G19/'Data Sheet'!G$17,0) -> 0.030887914 | I7: =IFERROR('Data Sheet'!H19/'Data Sheet'!H$17,0) -> 0.034531194 | J7: =IFERROR('Data Sheet'!I19/'Data Sheet'!I$17,0) -> 0.005431343 | ... L7: =IFERROR('Data Sheet'!K19/'Data Sheet'!K$17,0) -> 0.0097113275
B8: Power and Fuel | C8: =IFERROR('Data Sheet'!B20/'Data Sheet'!B$17,0) -> 0.037015469 | D8: =IFERROR('Data Sheet'!C20/'Data Sheet'!C$17,0) -> 0.037277745 | E8: =IFERROR('Data Sheet'!D20/'Data Sheet'!D$17,0) -> 0.029962857 | F8: =IFERROR('Data Sheet'!E20/'Data Sheet'!E$17,0) -> 0.025303388 | G8: =IFERROR('Data Sheet'!F20/'Data Sheet'!F$17,0) -> 0.028337554 | H8: =IFERROR('Data Sheet'!G20/'Data Sheet'!G$17,0) -> 0.025770398 | I8: =IFERROR('Data Sheet'!H20/'Data Sheet'!H$17,0) -> 0.028596662 | J8: =IFERROR('Data Sheet'!I20/'Data Sheet'!I$17,0) -> 0.024622904 | ... L8: =IFERROR('Data Sheet'!K20/'Data Sheet'!K$17,0) -> 0
B9: Other Mfr. Exp | C9: =IFERROR('Data Sheet'!B21/'Data Sheet'!B$17,0) -> 0.032600328 | D9: =IFERROR('Data Sheet'!C21/'Data Sheet'!C$17,0) -> 0.024796391 | E9: =IFERROR('Data Sheet'!D21/'Data Sheet'!D$17,0) -> 0.021462618 | F9: =IFERROR('Data Sheet'!E21/'Data Sheet'!E$17,0) -> 0.019162732 | G9: =IFERROR('Data Sheet'!F21/'Data Sheet'!F$17,0) -> 0.016484848 | H9: =IFERROR('Data Sheet'!G21/'Data Sheet'!G$17,0) -> 0.017524792 | I9: =IFERROR('Data Sheet'!H21/'Data Sheet'!H$17,0) -> 0.022430499 | J9: =IFERROR('Data Sheet'!I21/'Data Sheet'!I$17,0) -> 0.020328328 | ... L9: =IFERROR('Data Sheet'!K21/'Data Sheet'!K$17,0) -> 0
B10: Employee Cost | C10: =IFERROR('Data Sheet'!B22/'Data Sheet'!B$17,0) -> 0.027596281 | D10: =IFERROR('Data Sheet'!C22/'Data Sheet'!C$17,0) -> 0.024366529 | E10: =IFERROR('Data Sheet'!D22/'Data Sheet'!D$17,0) -> 0.021972879 | F10: =IFERROR('Data Sheet'!E22/'Data Sheet'!E$17,0) -> 0.023588898 | G10: =IFERROR('Data Sheet'!F22/'Data Sheet'!F$17,0) -> 0.031775204 | H10: =IFERROR('Data Sheet'!G22/'Data Sheet'!G$17,0) -> 0.027002633 | I10: =IFERROR('Data Sheet'!H22/'Data Sheet'!H$17,0) -> 0.028379865 | J10: =IFERROR('Data Sheet'!I22/'Data Sheet'!I$17,0) -> 0.028562657 | ... L10: =IFERROR('Data Sheet'!K22/'Data Sheet'!K$17,0) -> 0.028677124
B11: Selling and admin | C11: =IFERROR('Data Sheet'!B23/'Data Sheet'!B$17,0) -> 0.060930272 | D11: =IFERROR('Data Sheet'!C23/'Data Sheet'!C$17,0) -> 0.074486404 | E11: =IFERROR('Data Sheet'!D23/'Data Sheet'!D$17,0) -> 0.088364826 | F11: =IFERROR('Data Sheet'!E23/'Data Sheet'!E$17,0) -> 0.1049509 | G11: =IFERROR('Data Sheet'!F23/'Data Sheet'!F$17,0) -> 0.12042281 | H11: =IFERROR('Data Sheet'!G23/'Data Sheet'!G$17,0) -> 0.091428629 | I11: =IFERROR('Data Sheet'!H23/'Data Sheet'!H$17,0) -> 0.076870501 | J11: =IFERROR('Data Sheet'!I23/'Data Sheet'!I$17,0) -> 0.085971608 | ... L11: =IFERROR('Data Sheet'!K23/'Data Sheet'!K$17,0) -> 0
B12: Other Expenses | C12: =IFERROR('Data Sheet'!B24/'Data Sheet'!B$17,0) -> -0.0089520125 | D12: =IFERROR('Data Sheet'!C24/'Data Sheet'!C$17,0) -> -0.0098561241 | E12: =IFERROR('Data Sheet'!D24/'Data Sheet'!D$17,0) -> -0.0041102374 | F12: =IFERROR('Data Sheet'!E24/'Data Sheet'!E$17,0) -> -0.0017697958 | G12: =IFERROR('Data Sheet'!F24/'Data Sheet'!F$17,0) -> 0.0020244174 | H12: =IFERROR('Data Sheet'!G24/'Data Sheet'!G$17,0) -> 0.0010839632 | I12: =IFERROR('Data Sheet'!H24/'Data Sheet'!H$17,0) -> 0.0098517109 | J12: =IFERROR('Data Sheet'!I24/'Data Sheet'!I$17,0) -> 0.0086937081 | ... L12: =IFERROR('Data Sheet'!K24/'Data Sheet'!K$17,0) -> 0.15066793
B13: Other Income | C13: =IFERROR('Data Sheet'!B25/'Data Sheet'!B$17,0) -> 0.030340117 | D13: =IFERROR('Data Sheet'!C25/'Data Sheet'!C$17,0) -> 0.02525184 | E13: =IFERROR('Data Sheet'!D25/'Data Sheet'!D$17,0) -> 0.01479052 | F13: =IFERROR('Data Sheet'!E25/'Data Sheet'!E$17,0) -> 0.014362832 | G13: =IFERROR('Data Sheet'!F25/'Data Sheet'!F$17,0) -> 0.048105647 | H13: =IFERROR('Data Sheet'!G25/'Data Sheet'!G$17,0) -> 0.028214714 | I13: =IFERROR('Data Sheet'!H25/'Data Sheet'!H$17,0) -> 0.013715261 | J13: =IFERROR('Data Sheet'!I25/'Data Sheet'!I$17,0) -> 0.017565384 | ... L13: =IFERROR('Data Sheet'!K25/'Data Sheet'!K$17,0) -> 0.027394513
B14: Depreciation | C14: =IFERROR('Data Sheet'!B26/'Data Sheet'!B$17,0) -> 0.038315008 | D14: =IFERROR('Data Sheet'!C26/'Data Sheet'!C$17,0) -> 0.042745693 | E14: =IFERROR('Data Sheet'!D26/'Data Sheet'!D$17,0) -> 0.03683378 | F14: =IFERROR('Data Sheet'!E26/'Data Sheet'!E$17,0) -> 0.037210963 | G14: =IFERROR('Data Sheet'!F26/'Data Sheet'!F$17,0) -> 0.056983918 | H14: =IFERROR('Data Sheet'!G26/'Data Sheet'!G$17,0) -> 0.04287197 | I14: =IFERROR('Data Sheet'!H26/'Data Sheet'!H$17,0) -> 0.045987202 | J14: =IFERROR('Data Sheet'!I26/'Data Sheet'!I$17,0) -> 0.056540247 | ... L14: =IFERROR('Data Sheet'!K26/'Data Sheet'!K$17,0) -> 0.0545658
B15: Interest | C15: =IFERROR('Data Sheet'!B27/'Data Sheet'!B$17,0) -> 0.0126631 | D15: =IFERROR('Data Sheet'!C27/'Data Sheet'!C$17,0) -> 0.020602677 | E15: =IFERROR('Data Sheet'!D27/'Data Sheet'!D$17,0) -> 0.029023273 | F15: =IFERROR('Data Sheet'!E27/'Data Sheet'!E$17,0) -> 0.036915997 | G15: =IFERROR('Data Sheet'!F27/'Data Sheet'!F$17,0) -> 0.045440021 | H15: =IFERROR('Data Sheet'!G27/'Data Sheet'!G$17,0) -> 0.02099405 | I15: =IFERROR('Data Sheet'!H27/'Data Sheet'!H$17,0) -> 0.022331229 | J15: =IFERROR('Data Sheet'!I27/'Data Sheet'!I$17,0) -> 0.025714066 | ... L15: =IFERROR('Data Sheet'!K27/'Data Sheet'!K$17,0) -> 0.0255964
B16: Profit before tax | C16: =IFERROR('Data Sheet'!B28/'Data Sheet'!B$17,0) -> 0.13171072 | D16: =IFERROR('Data Sheet'!C28/'Data Sheet'!C$17,0) -> 0.12646646 | E16: =IFERROR('Data Sheet'!D28/'Data Sheet'!D$17,0) -> 0.09717298 | F16: =IFERROR('Data Sheet'!E28/'Data Sheet'!E$17,0) -> 0.089840601 | G16: =IFERROR('Data Sheet'!F28/'Data Sheet'!F$17,0) -> 0.11893667 | H16: =IFERROR('Data Sheet'!G28/'Data Sheet'!G$17,0) -> 0.12065389 | I16: =IFERROR('Data Sheet'!H28/'Data Sheet'!H$17,0) -> 0.10778689 | J16: =IFERROR('Data Sheet'!I28/'Data Sheet'!I$17,0) -> 0.116057 | ... L16: =IFERROR('Data Sheet'!K28/'Data Sheet'!K$17,0) -> 0.1164962
... B19: Dividend Amount | C19: =IFERROR('Data Sheet'!B31/'Data Sheet'!B$17,0) -> 0.010708528 | D19: =IFERROR('Data Sheet'!C31/'Data Sheet'!C$17,0) -> 0.0090915837 | E19: =IFERROR('Data Sheet'!D31/'Data Sheet'!D$17,0) -> 0.0067774929 | F19: =IFERROR('Data Sheet'!E31/'Data Sheet'!E$17,0) -> 0.0069054718 | G19: =IFERROR('Data Sheet'!F31/'Data Sheet'!F$17,0) -> 0.0096749566 | H19: =IFERROR('Data Sheet'!G31/'Data Sheet'!G$17,0) -> 0.0077907159 | I19: =IFERROR('Data Sheet'!H31/'Data Sheet'!H$17,0) -> 0.0069482289 | J19: =IFERROR('Data Sheet'!I31/'Data Sheet'!I$17,0) -> 0.0075257969 | ... L19: =IFERROR('Data Sheet'!K31/'Data Sheet'!K$17,0) -> 0.0076797712
B22: ="Common Size Balance Sheet"&""&"-"&'Data Sheet'!B1 -> Common Size Balance Sheet-RELIANCE INDUSTRIES LTD
B24: Particulars | C24: ='Data Sheet'!B16 -> 42825 | D24: ='Data Sheet'!C16 -> 43190 | E24: ='Data Sheet'!D16 -> 43555 | F24: ='Data Sheet'!E16 -> 43921 | G24: ='Data Sheet'!F16 -> 44286 | H24: ='Data Sheet'!G16 -> 44651 | I24: ='Data Sheet'!H16 -> 45016 | J24: ='Data Sheet'!I16 -> 45382 | ... L24: ='Data Sheet'!K16 -> 46112
B25: Total Liabilities | C25: ='Data Sheet'!B61/'Data Sheet'!B$61 -> 1 | D25: ='Data Sheet'!C61/'Data Sheet'!C$61 -> 1 | E25: ='Data Sheet'!D61/'Data Sheet'!D$61 -> 1 | F25: ='Data Sheet'!E61/'Data Sheet'!E$61 -> 1 | G25: ='Data Sheet'!F61/'Data Sheet'!F$61 -> 1 | H25: ='Data Sheet'!G61/'Data Sheet'!G$61 -> 1 | I25: ='Data Sheet'!H61/'Data Sheet'!H$61 -> 1 | J25: ='Data Sheet'!I61/'Data Sheet'!I$61 -> 1 | ... L25: ='Data Sheet'!K61/'Data Sheet'!K$61 -> 1
B26: ='Data Sheet'!A57 -> Equity Share Capital | C26: ='Data Sheet'!B57/'Data Sheet'!B$61 -> 0.0041864624 | D26: ='Data Sheet'!C57/'Data Sheet'!C$61 -> 0.007299639 | E26: ='Data Sheet'!D57/'Data Sheet'!D$61 -> 0.005940078 | F26: ='Data Sheet'!E57/'Data Sheet'!E$61 -> 0.0054504886 | G26: ='Data Sheet'!F57/'Data Sheet'!F$61 -> 0.0048823353 | H26: ='Data Sheet'!G57/'Data Sheet'!G$61 -> 0.004514147 | I26: ='Data Sheet'!H57/'Data Sheet'!H$61 -> 0.004213261 | J26: ='Data Sheet'!I57/'Data Sheet'!I$61 -> 0.0038551652 | ... L26: ='Data Sheet'!K57/'Data Sheet'!K$61 -> 0.0062126401
B27: ='Data Sheet'!A58 -> Reserves | C27: ='Data Sheet'!B58/'Data Sheet'!B$61 -> 0.3689152 | D27: ='Data Sheet'!C58/'Data Sheet'!C$61 -> 0.35448487 | E27: ='Data Sheet'!D58/'Data Sheet'!D$61 -> 0.38209156 | F27: ='Data Sheet'!E58/'Data Sheet'!E$61 -> 0.38075777 | G27: ='Data Sheet'!F58/'Data Sheet'!F$61 -> 0.52552488 | H27: ='Data Sheet'!G58/'Data Sheet'!G$61 -> 0.51562035 | I27: ='Data Sheet'!H58/'Data Sheet'!H$61 -> 0.44156794 | J27: ='Data Sheet'!I58/'Data Sheet'!I$61 -> 0.4482584 | ... L27: ='Data Sheet'!K58/'Data Sheet'!K$61 -> 0.40883414
B28: ='Data Sheet'!A59 -> Borrowings | C28: ='Data Sheet'!B59/'Data Sheet'!B$61 -> 0.30768872 | D28: ='Data Sheet'!C59/'Data Sheet'!C$61 -> 0.29563784 | E28: ='Data Sheet'!D59/'Data Sheet'!D$61 -> 0.30844501 | F28: ='Data Sheet'!E59/'Data Sheet'!E$61 -> 0.30535548 | G28: ='Data Sheet'!F59/'Data Sheet'!F$61 -> 0.21132444 | H28: ='Data Sheet'!G59/'Data Sheet'!G$61 -> 0.21296765 | I28: ='Data Sheet'!H59/'Data Sheet'!H$61 -> 0.28125603 | J28: ='Data Sheet'!I59/'Data Sheet'!I$61 -> 0.19983442 | ... L28: ='Data Sheet'!K59/'Data Sheet'!K$61 -> 0.18272471
B29: ='Data Sheet'!A60 -> Other Liabilities | C29: ='Data Sheet'!B60/'Data Sheet'!B$61 -> 0.31920962 | D29: ='Data Sheet'!C60/'Data Sheet'!C$61 -> 0.34257765 | E29: ='Data Sheet'!D60/'Data Sheet'!D$61 -> 0.30352335 | F29: ='Data Sheet'!E60/'Data Sheet'!E$61 -> 0.30843626 | G29: ='Data Sheet'!F60/'Data Sheet'!F$61 -> 0.25826834 | H29: ='Data Sheet'!G60/'Data Sheet'!G$61 -> 0.26689786 | I29: ='Data Sheet'!H60/'Data Sheet'!H$61 -> 0.27296277 | J29: ='Data Sheet'!I60/'Data Sheet'!I$61 -> 0.34805202 | ... L29: ='Data Sheet'!K60/'Data Sheet'!K$61 -> 0.40222851
B31: Total Assets | C31: ='Data Sheet'!B75/'Data Sheet'!B$75 -> 1 | D31: ='Data Sheet'!C75/'Data Sheet'!C$75 -> 1 | E31: ='Data Sheet'!D75/'Data Sheet'!D$75 -> 1 | F31: ='Data Sheet'!E75/'Data Sheet'!E$75 -> 1 | G31: ='Data Sheet'!F75/'Data Sheet'!F$75 -> 1 | H31: ='Data Sheet'!G75/'Data Sheet'!G$75 -> 1 | I31: ='Data Sheet'!H75/'Data Sheet'!H$75 -> 1 | J31: ='Data Sheet'!I75/'Data Sheet'!I$75 -> 1 | ... L31: ='Data Sheet'!K75/'Data Sheet'!K$75 -> 1
B32: ='Data Sheet'!A62 -> Net Block | C32: ='Data Sheet'!B62/'Data Sheet'!B$75 -> 0.28087923 | D32: ='Data Sheet'!C62/'Data Sheet'!C$75 -> 0.49784105 | E32: ='Data Sheet'!D62/'Data Sheet'!D$75 -> 0.39932039 | F32: ='Data Sheet'!E62/'Data Sheet'!E$75 -> 0.45799753 | G32: ='Data Sheet'!F62/'Data Sheet'!F$75 -> 0.41002375 | H32: ='Data Sheet'!G62/'Data Sheet'!G$75 -> 0.41891684 | I32: ='Data Sheet'!H62/'Data Sheet'!H$75 -> 0.45134387 | J32: ='Data Sheet'!I62/'Data Sheet'!I$75 -> 0.44442374 | ... L32: ='Data Sheet'!K62/'Data Sheet'!K$75 -> 0.53724462
B33: ='Data Sheet'!A63 -> Capital Work in Progress | C33: ='Data Sheet'!B63/'Data Sheet'!B$75 -> 0.45958698 | D33: ='Data Sheet'!C63/'Data Sheet'!C$75 -> 0.23052906 | E33: ='Data Sheet'!D63/'Data Sheet'!D$75 -> 0.17988934 | F33: ='Data Sheet'!E63/'Data Sheet'!E$75 -> 0.093813063 | G33: ='Data Sheet'!F63/'Data Sheet'!F$75 -> 0.095414241 | H33: ='Data Sheet'!G63/'Data Sheet'!G$75 -> 0.11510975 | I33: ='Data Sheet'!H63/'Data Sheet'!H$75 -> 0.18292253 | J33: ='Data Sheet'!I63/'Data Sheet'!I$75 -> 0.19307449 | ... L33: ='Data Sheet'!K63/'Data Sheet'!K$75 -> 0.088280368
B34: ='Data Sheet'!A64 -> Investments | C34: ='Data Sheet'!B64/'Data Sheet'!B$75 -> 0.11728744 | D34: ='Data Sheet'!C64/'Data Sheet'!C$75 -> 0.10213824 | E34: ='Data Sheet'!D64/'Data Sheet'!D$75 -> 0.23619478 | F34: ='Data Sheet'!E64/'Data Sheet'!E$75 -> 0.23797371 | G34: ='Data Sheet'!F64/'Data Sheet'!F$75 -> 0.27637124 | H34: ='Data Sheet'!G64/'Data Sheet'!G$75 -> 0.26308435 | I34: ='Data Sheet'!H64/'Data Sheet'!H$75 -> 0.14668575 | J34: ='Data Sheet'!I64/'Data Sheet'!I$75 -> 0.12858452 | ... L34: ='Data Sheet'!K64/'Data Sheet'!K$75 -> 0.11401104
B35: ='Data Sheet'!A65 -> Other Assets | C35: ='Data Sheet'!B74/'Data Sheet'!B$75 -> 0.057143302 | D35: ='Data Sheet'!C74/'Data Sheet'!C$75 -> 0.067618422 | E35: ='Data Sheet'!D74/'Data Sheet'!D$75 -> 0.075606187 | F35: ='Data Sheet'!E74/'Data Sheet'!E$75 -> 0.1031844 | G35: ='Data Sheet'!F74/'Data Sheet'!F$75 -> 0.12873836 | H35: ='Data Sheet'!G74/'Data Sheet'!G$75 -> 0.09105565 | I35: ='Data Sheet'!H74/'Data Sheet'!H$75 -> 0.071390675 | J35: ='Data Sheet'!I74/'Data Sheet'!I$75 -> 0.073452692 | ... L35: ='Data Sheet'!K74/'Data Sheet'!K$75 -> 0.089947386
B36: ='Data Sheet'!A67 -> Receivables | C36: ='Data Sheet'!B67/'Data Sheet'!B$75 -> 0.011569011 | D36: ='Data Sheet'!C67/'Data Sheet'!C$75 -> 0.021638832 | E36: ='Data Sheet'!D67/'Data Sheet'!D$75 -> 0.03016048 | F36: ='Data Sheet'!E67/'Data Sheet'!E$75 -> 0.0169009 | G36: ='Data Sheet'!F67/'Data Sheet'!F$75 -> 0.014403836 | H36: ='Data Sheet'!G67/'Data Sheet'!G$75 -> 0.015774491 | I36: ='Data Sheet'!H67/'Data Sheet'!H$75 -> 0.017714876 | J36: ='Data Sheet'!I67/'Data Sheet'!I$75 -> 0.01802116 | ... L36: ='Data Sheet'!K67/'Data Sheet'!K$75 -> 0.026853646
B37: ='Data Sheet'!A68 -> Inventory | C37: ='Data Sheet'!B68/'Data Sheet'!B$75 -> 0.06925702 | D37: ='Data Sheet'!C68/'Data Sheet'!C$75 -> 0.074989553 | E37: ='Data Sheet'!D68/'Data Sheet'!D$75 -> 0.0677215 | F37: ='Data Sheet'!E68/'Data Sheet'!E$75 -> 0.063544322 | G37: ='Data Sheet'!F68/'Data Sheet'!F$75 -> 0.061869681 | H37: ='Data Sheet'!G68/'Data Sheet'!G$75 -> 0.071918069 | I37: ='Data Sheet'!H68/'Data Sheet'!H$75 -> 0.087184488 | J37: ='Data Sheet'!I68/'Data Sheet'!I$75 -> 0.087046052 | ... L37: ='Data Sheet'!K68/'Data Sheet'!K$75 -> 0.076643834
B38: ='Data Sheet'!A69 -> Cash & Bank | C38: ='Data Sheet'!B69/'Data Sheet'!B$75 -> 0.0042770111 | D38: ='Data Sheet'!C69/'Data Sheet'!C$75 -> 0.0052448436 | E38: ='Data Sheet'!D69/'Data Sheet'!D$75 -> 0.011107324 | F38: ='Data Sheet'!E69/'Data Sheet'!E$75 -> 0.026586072 | G38: ='Data Sheet'!F69/'Data Sheet'!F$75 -> 0.013178896 | H38: ='Data Sheet'!G69/'Data Sheet'!G$75 -> 0.024140844 | I38: ='Data Sheet'!H69/'Data Sheet'!H$75 -> 0.042757812 | J38: ='Data Sheet'!I69/'Data Sheet'!I$75 -> 0.055397345 | ... L38: ='Data Sheet'!K69/'Data Sheet'!K$75 -> 0.067019108

Sheet Forecasting
B2: ='Data Sheet'!B1&" - "&"Sales Forecasting" -> RELIANCE INDUSTRIES LTD - Sales Forecasting | G2: ='Data Sheet'!B1&" - "&"EBITDA Forecasting" -> RELIANCE INDUSTRIES LTD - EBITDA Forecasting | L2: ='Data Sheet'!B1&" - "&"Earning Per Share Forecasting" -> RELIANCE INDUSTRIES LTD - Earning Per Share Forecasting
B3: Year Weight | C3: Year | D3: Sales | E3: Sales Growth | G3: Year Weight | H3: Year | I3: EBITDA | J3: Sales Growth | L3: Year Weight | M3: Year | N3: EBITDA | O3: Sales Growth
B4: 1 | C4: 2017 | D4: {=TRANSPOSE('Data Sheet'!B17:K17)} -> 303954 | G4: 1 | H4: ='Data Sheet'!$B$16 -> 42825 | I4: {=TRANSPOSE(HistoricalFS!C19:L19)} -> 55529 | L4: 1 | M4: ='Data Sheet'!$B$16 -> 42825 | N4: {=TRANSPOSE(HistoricalFS!C41:L41)} -> 21.505601
B5: 2 | C5: 2018 | D5: 390823 | E5: =IFERROR(D5/D4-1,0) -> 0.28579654 | G5: 2 | H5: =H4+365 -> 43190 | I5: 74184 | J5: =I5/I4-1 -> 0.33595058 | L5: 2 | M5: =M4+365 -> 43190 | N5: 26.698436 | O5: =N5/N4-1 -> 0.24146432
B6: 3 | C6: 2019 | D6: 568337 | E6: =IFERROR(D6/D5-1,0) -> 0.45420561 | G6: 3 | H6: =H5+365 -> 43555 | I6: 92656 | J6: =I6/I5-1 -> 0.24900248 | L6: 3 | M6: =M5+365 -> 43555 | N6: 29.459571 | O6: =N6/N5-1 -> 0.10341935
